<?xml version="1.0" ?>
<robot name="ur10" xmlns:xacro="http://www.ros.org/wiki/xacro">
  
  <material name="blue">
      <color rgba="0.0 0.0 1.0 1.0"/>
  </material>
  <material name="white">
      <color rgba="1.0 1.0 1.0 1.0"/>
  </material>
  <material name="black">
      <color rgba="0.0 0.0 0.0 1.0"/>
  </material>
  <material name="gray">
   		<color rgba="0.5 0.5 0.5 1"/>
  </material>

  <material name="LightGrey">
      <color rgba="0.7 0.7 0.7 1.0"/>
  </material>

  <link name="world"/>

  <joint name="world_joint" type="fixed">
    <parent link="world"/>
    <child link="base_link"/>
    <origin rpy="0.0 0.0 0.0" xyz="0.0 0.0 0.0"/>
  </joint>

<!-- UR 10 -->
  <link name="base_link">
    <visual>
      <geometry>
        <mesh filename="meshes/ur10/Base.dae"/>
      </geometry>
      <material name="LightGrey"/>
    </visual>
    <collision>
       <!-- corrected-->
      <origin rpy="0 0 0" xyz="0.000 0.0 0.-15"/>
      <geometry>
         <!-- corrected-->
        <cylinder length="0.10" radius="0.085" />
        <!-- <mesh filename="meshes/ur10/Base.obj"/> -->
      </geometry>
    </collision>
    <collision>
      <!-- added-->
      <origin rpy="0 0 0" xyz="0.0 0.0 0.135"/>
      <geometry>
        <cylinder length="0.155" radius="0.076" />
      </geometry>
    </collision>
    <inertial>
      <mass value="4.0"/>
      <origin rpy="0 0 0" xyz="0.0 0.0 0.0"/>
      <inertia ixx="0.0061063308908" ixy="0.0" ixz="0.0" iyy="0.0061063308908" iyz="0.0" izz="0.01125"/>
    </inertial>
     <contact_coefficients kd="1.0" kp="1000.0" mu="0"/>
  </link>

  <joint name="shoulder_pan_joint" type="revolute">
    <parent link="base_link"/>
    <child link="shoulder_link"/>
    <origin rpy="0.0 0.0 0.0" xyz="0.0 0.0 0.1273"/>
    <axis xyz="0 0 1"/>
    <limit effort="330.0" lower="-6.2831853" upper="6.2831853" velocity="2.16"/>
    <dynamics damping="0.0" friction="0.0"/>
  </joint>

  <link name="shoulder_link">
    <visual>
      <geometry>
        <mesh filename="meshes/ur10/Shoulder.dae"/>
      </geometry>
      <material name="LightGrey"/>
    </visual>
    <collision>
      <!-- corrected-->
      <origin rpy="1.57079632679 0 0" xyz="0.0 0.18 -0.0"/>
      <geometry>
       <!-- corrected-->
        <cylinder length="0.17" radius="0.08" />
        <!-- <mesh filename="meshes/ur10/Shoulder.obj"/>  -->
      </geometry>
    </collision>
    <inertial>
      <mass value="7.778"/>
      <origin rpy="0 0 0" xyz="0.0 0.0 0.0"/>
      <inertia ixx="0.0314743125769" ixy="0.0" ixz="0.0" iyy="0.0314743125769" iyz="0.0" izz="0.021875625"/>
    </inertial>
    <contact_coefficients kd="1.0" kp="1000.0" mu="0"/>
  </link>
  
  <joint name="shoulder_lift_joint" type="revolute">
    <parent link="shoulder_link"/>
    <child link="upper_arm_link"/>
    <origin rpy="0.0 1.570796325 0.0" xyz="0.0 0.220941 0.0"/>
    <axis xyz="0 1 0"/>
    <limit effort="330.0" lower="-6.2831853" upper="6.2831853" velocity="2.16"/>
    <dynamics damping="0.0" friction="0.0"/>
  </joint>
  
  <link name="upper_arm_link">
    <visual>
      <geometry>
        <mesh filename="meshes/ur10/UpperArm.dae"/>
      </geometry>
      <material name="LightGrey"/>
    </visual>
    <collision>
      <!-- corrected-->
      <origin rpy="0 0 0" xyz="0.0 -0.045 0.320"/>
      <geometry>
        <!-- corrected-->
        <cylinder length="0.70" radius="0.06" />
        <!-- <mesh filename="meshes/ur10/UpperArm.obj"/> -->
      </geometry>
    </collision>
    <collision>
      <!-- added-->
      <origin rpy="0 1.57 1.57" xyz="0 -0.04 0.61"/>
      <geometry>
        <cylinder length="0.125" radius="0.06" />
      </geometry>
    </collision>
    <inertial>
      <mass value="12.93"/>
      <origin rpy="0 0 0" xyz="0.0 0.0 0.306"/>
      <inertia ixx="0.421753803798" ixy="0.0" ixz="0.0" iyy="0.421753803798" iyz="0.0" izz="0.036365625"/>
    </inertial>
    <contact_coefficients kd="1.0" kp="1000.0" mu="0"/>
  </link>
  
  <joint name="elbow_joint" type="revolute">
    <parent link="upper_arm_link"/>
    <child link="forearm_link"/>
    <origin rpy="0.0 0.0 0.0" xyz="0.0 -0.1719 0.612"/>
    <axis xyz="0 1 0"/>
    <limit effort="150.0" lower="-6.2831853" upper="6.2831853" velocity="3.15"/>
    <dynamics damping="0.0" friction="0.0"/>
  </joint>
  
  <link name="forearm_link">
    <visual>
      <geometry>
        <mesh filename="meshes/ur10/Forearm.dae"/>
      </geometry>
      <material name="LightGrey"/>
    </visual>
    <collision>
      <!-- <origin rpy="1.57079632679 0 0" xyz="0.0 0.00 -0.0"/> -->
      <!-- corrected-->
      <origin rpy="0 0 0" xyz="0 0.0 0.28"/>
      <geometry>
        <!-- corrected-->
        <cylinder length="0.675" radius="0.047" />
        <!-- <mesh filename="meshes/ur10/Forearm.obj"/> -->
      </geometry>
    </collision>
    <collision>
      <!-- added-->
      <origin rpy="0 1.57 1.57" xyz="0 -0.003 0"/>
      <geometry>
        <cylinder length="0.13" radius="0.060" />
      </geometry>
    </collision>
    <inertial>
      <mass value="3.87"/>
      <origin rpy="0 0 0" xyz="0.0 0.0 0.28615"/>
      <inertia ixx="0.111069694097" ixy="0.0" ixz="0.0" iyy="0.111069694097" iyz="0.0" izz="0.010884375"/>
    </inertial>
    <contact_coefficients kd="1.0" kp="1000.0" mu="0"/>    
  </link>
  
  <joint name="wrist_1_joint" type="revolute">
    <parent link="forearm_link"/>
    <child link="wrist_1_link"/>
    <origin rpy="0.0 1.570796325 0.0" xyz="0.0 0.0 0.5723"/>
    <axis xyz="0 1 0"/>
    <limit effort="54.0" lower="-6.2831853" upper="6.2831853" velocity="3.2"/>
    <dynamics damping="0.0" friction="0.0"/>
  </joint>
  
  <link name="wrist_1_link">
    <visual>
      <geometry>
        <mesh filename="meshes/ur10/Wrist1.dae"/>
      </geometry>
      <material name="LightGrey"/>
    </visual>
    <collision>
      <!-- <origin rpy="1.57079632679 0 0" xyz="0.0 0.1100 -0.0"/> -->
      <!-- corrected-->
      <origin rpy="0 0 0" xyz="0.0 0.115 0.0025"/>
      <geometry>
      <!-- corrected-->
      <cylinder length="0.115" radius="0.047" />
        <!-- <mesh filename="meshes/ur10/Wrist1.obj"/> -->
      </geometry>
    </collision>
    <collision>
      <!-- added-->
      <origin rpy="0 1.57 1.57" xyz="0 -0.003 0"/>
      <geometry>
        <cylinder length="0.13" radius="0.047" />
      </geometry>
    </collision>
    <inertial>
      <mass value="1.96"/>
      <origin rpy="0 0 0" xyz="0.0 0.0 0.0"/>
      <inertia ixx="0.0051082479567" ixy="0.0" ixz="0.0" iyy="0.0051082479567" iyz="0.0" izz="0.0055125"/>
    </inertial>
    <contact_coefficients kd="1.0" kp="1000.0" mu="0"/>
  </link>
  
  <joint name="wrist_2_joint" type="revolute">
    <parent link="wrist_1_link"/>
    <child link="wrist_2_link"/>
    <origin rpy="0.0 0.0 0.0" xyz="0.0 0.1149 0.0"/>
    <axis xyz="0 0 1"/>
    <limit effort="54.0" lower="-6.2831853" upper="6.2831853" velocity="3.2"/>
    <dynamics damping="0.0" friction="0.0"/>
  </joint>
  
  <link name="wrist_2_link">
    <visual>
      <geometry>
        <mesh filename="meshes/ur10/Wrist2.dae"/>
      </geometry>
      <material name="LightGrey"/>
    </visual>
    <collision>
      <!-- corrected-->
      <origin rpy="1.57079632679 0 0" xyz="0.0 0.02 0.115"/>
      <geometry>
      <!-- corrected-->
      <cylinder length="0.15" radius="0.046" />
        <!-- <mesh filename="meshes/ur10/Wrist2.obj"/> -->
      </geometry>
    </collision>
    <inertial>
      <mass value="1.96"/>
      <origin rpy="0 0 0" xyz="0.0 0.0 0.0"/>
      <inertia ixx="0.0051082479567" ixy="0.0" ixz="0.0" iyy="0.0051082479567" iyz="0.0" izz="0.0055125"/>
    </inertial>
    <contact_coefficients kd="1.0" kp="1000.0" mu="0"/>
  </link>
  
  <joint name="wrist_3_joint" type="revolute">
    <parent link="wrist_2_link"/>
    <child link="wrist_3_link"/>
    <origin rpy="0.0 0.0 0.0" xyz="0.0 0.0 0.1157"/>
    <axis xyz="0 1 0"/>
    <limit effort="54.0" lower="-6.2831853" upper="6.2831853" velocity="3.2"/>
    <dynamics damping="0.0" friction="0.0"/>
  </joint>
  
  <link name="wrist_3_link">
    <visual>
      <geometry>
        <mesh filename="meshes/ur10/Wrist3.dae"/>
      </geometry>
      <material name="LightGrey"/>
    </visual>
	  <collision>
      <origin rpy="1.57079632679 0 0" xyz="0.0 0.115 0.0"/>
      <geometry>
        <cylinder length="0.025" radius="0.046" />
      </geometry>
    </collision>
    <inertial>
      <mass value="0.202"/>
      <origin rpy="0 0 0" xyz="0.0 0.0 0.0"/>
      <inertia ixx="0.000526462289415" ixy="0.0" ixz="0.0" iyy="0.000526462289415" iyz="0.0" izz="0.000568125"/>
    </inertial>
    <contact_coefficients kd="1.0" kp="1000.0" mu="0"/>
  </link>

  <joint name="ee_fixed_joint" type="fixed">
    <parent link="wrist_3_link"/>
    <child link="ee_link"/>
    <origin rpy="0.0 0.0 1.570796325" xyz="0.0 0.0922 0.0"/>
  </joint>
  
  <link name="ee_link">
      <visual>
          <origin xyz="0.0 0 0" rpy="0 0 0" />
          <geometry>
             <sphere radius="0.01"/>
          </geometry>
          <material name="red">
        		<color rgba="1 0 0 1"/>
      	  </material>
      </visual>
  </link>
 
 <!-- WSG50-110 -->

  <link name="wsg50_holder_link">
    <inertial>
        <mass value="0.3" />
        <origin xyz="0 0 0" />
        <inertia  ixx="1.0" ixy="0.0"  ixz="0.0"  iyy="1.0"  iyz="0.0"  izz="1.0" />
    </inertial>
    <visual>
        <origin xyz="0.0 0 0" rpy="0 0 0" />
        <geometry>
            <mesh filename="meshes/wsg50/wsg50-holder.stl" scale="0.001 0.001 0.001"/>
        </geometry>
        <material name="white"/>
    </visual>
    <collision>
        <origin xyz="0.0 0 0" rpy="0 0 0" />
        <geometry>
            <mesh filename="meshes/wsg50/wsg50-holder.stl" scale="0.001 0.001 0.001"/>
        </geometry>
    </collision>
    <contact_coefficients kd="1.0" kp="1000.0" mu="0"/>
  </link>

  <joint name="wsg50_holder_joint" type="fixed">
    <origin rpy="0 -1.570796325 0" xyz="0 0 0"/>
    <parent link="ee_link" />
    <child link="wsg50_holder_link" />
  </joint>

  <link name="wsg50_base_link">
    <inertial>
        <mass value="1.2" />
        <origin xyz="0 0 0" />
        <inertia  ixx="1.0" ixy="0.0"  ixz="0.0"  iyy="1.0"  iyz="0.0"  izz="1.0" />
    </inertial>
    <visual>
        <origin xyz="0.0 0 0" rpy="0 0 0" />
        <geometry>
            <mesh filename="meshes/wsg50/wsg50-110-base.stl" scale="0.001 0.001 0.001"/>
        </geometry>
        <material name="gray"/>
    </visual>
    <collision>
        <origin xyz="0.0 0 0" rpy="0 0 0" />
        <geometry>
            <mesh filename="meshes/wsg50/wsg50-110-base.stl" scale="0.001 0.001 0.001"/>
        </geometry>
    </collision>
    <contact_coefficients kd="1.0" kp="1000.0" mu="0"/>
  </link>

  <joint name="wsg50_base_holder_joint" type="fixed">
    <origin rpy="0 0 0" xyz="0 0 0"/>
    <parent link="wsg50_holder_link" />
    <child link="wsg50_base_link" />
  </joint>

 <!-- Finger - 1  -->
  <link name="wsg50_lip1_link">
    <inertial>
        <mass value="0.1" />
        <origin xyz="0 0 0" />
        <inertia  ixx="1.0" ixy="0.0"  ixz="0.0"  iyy="1.0"  iyz="0.0"  izz="1.0" />
    </inertial>
    <visual>
        <origin xyz="0.0 0 0" rpy="0 0 0" />
        <geometry>
            <mesh filename="meshes/wsg50/wsg50-lip-1.stl" scale="0.001 0.001 0.001"/>
        </geometry>
        <material name="gray"/>
    </visual>
    <collision>
        <origin xyz="0.0 0 0" rpy="0 0 0" />
        <geometry>
            <mesh filename="meshes/wsg50/wsg50-lip-1.stl" scale="0.001 0.001 0.001"/>
        </geometry>
    </collision>
    <contact_coefficients kd="1.0" kp="1000.0" mu="0"/>     
  </link>

  <joint name="wsg50_base_lip1_joint" type="prismatic">
    <parent link="wsg50_base_link"/>
    <child link="wsg50_lip1_link"/>
    <origin   xyz="0 0 0"   rpy="0 0 0"  />
    <axis xyz="0 -1 0"/>
    <limit effort="30" lower="0" upper="0.055" velocity="0.5"/>
  </joint>

  <link name="wsg50_finger1_link">
    <inertial>
        <mass value="0.1" />
        <origin xyz="0 0 0" />
        <inertia  ixx="1.0" ixy="0.0"  ixz="0.0"  iyy="1.0"  iyz="0.0"  izz="1.0" />
    </inertial>
    <visual>
        <origin xyz="0.0 0 0" rpy="0 0 0" />
        <geometry>
            <mesh filename="meshes/wsg50/wsg50-finger-1.stl" scale="0.001 0.001 0.001"/>
        </geometry>
        <material name="white"/>
    </visual>
    <collision>
        <origin xyz="0.0 0 0" rpy="0 0 0" />
        <geometry>
            <mesh filename="meshes/wsg50/wsg50-finger-1.stl" scale="0.001 0.001 0.001"/>
        </geometry>
    </collision>
    <contact_coefficients kd="1.0" kp="1000.0" mu="0"/>
  </link>

  <joint name="wsg50_lip1_finger1_joint" type="fixed">
    <origin rpy="0 0 0" xyz="0 0 0"/>
    <parent link="wsg50_lip1_link" />
    <child link="wsg50_finger1_link" />
  </joint>

  <link name="wsg50_tip1_link">
    <inertial>
        <mass value="0.05" />
        <origin xyz="0 0 0" />
        <inertia  ixx="1.0" ixy="0.0"  ixz="0.0"  iyy="1.0"  iyz="0.0"  izz="1.0" />
    </inertial>
    <visual>
        <origin xyz="0.0 0 0" rpy="0 0 0" />
        <geometry>
            <mesh filename="meshes/wsg50/wsg50-tip-1.stl" scale="0.001 0.001 0.001"/>
        </geometry>
        <material name="blue"/>
    </visual>
    <collision>
        <origin xyz="0.0 0 0" rpy="0 0 0" />
        <geometry>
            <mesh filename="meshes/wsg50/wsg50-tip-1.stl" scale="0.001 0.001 0.001"/>
        </geometry>
    </collision>
    <contact_coefficients kd="1.0" kp="1000.0" mu="0"/>
  </link>

  <joint name="wsg50_lip1_tip1_joint" type="fixed">
    <origin rpy="0 0 0" xyz="0 0 0"/>
    <parent link="wsg50_lip1_link" />
    <child link="wsg50_tip1_link" />
  </joint>

 <!-- Finger - 2  -->
  <link name="wsg50_lip2_link">
    <inertial>
        <mass value="0.1" />
        <origin xyz="0 0 0" />
        <inertia  ixx="1.0" ixy="0.0"  ixz="0.0"  iyy="1.0"  iyz="0.0"  izz="1.0" />
    </inertial>
    <visual>
        <origin xyz="0.0 0 0" rpy="0 0 0" />
        <geometry>
            <mesh filename="meshes/wsg50/wsg50-lip-2.stl" scale="0.001 0.001 0.001"/>
        </geometry>
        <material name="gray"/>
    </visual>
    <collision>
        <origin xyz="0.0 0 0" rpy="0 0 0" />
        <geometry>
            <mesh filename="meshes/wsg50/wsg50-lip-2.stl" scale="0.001 0.001 0.001"/>
        </geometry>
    </collision>
    <contact_coefficients kd="1.0" kp="1000.0" mu="0"/>
  </link>

  <joint name="wsg50_base_lip2_joint" type="prismatic">
    <parent link="wsg50_base_link"/>
    <child link="wsg50_lip2_link"/>
    <origin   xyz="0 0 0"   rpy="0 0 0"  />
    <axis xyz="0 1 0"/>
    <limit effort="30" lower="0" upper="0.055" velocity="50"/>
  </joint>

  <link name="wsg50_finger2_link">
    <inertial>
        <mass value="0.1" />
        <origin xyz="0 0 0" />
        <inertia  ixx="1.0" ixy="0.0"  ixz="0.0"  iyy="1.0"  iyz="0.0"  izz="1.0" />
    </inertial>
    <visual>
        <origin xyz="0.0 0 0" rpy="0 0 0" />
        <geometry>
            <mesh filename="meshes/wsg50/wsg50-finger-2.stl" scale="0.001 0.001 0.001"/>
        </geometry>
        <material name="white"/>
    </visual>
    <collision>
        <origin xyz="0.0 0 0" rpy="0 0 0" />
        <geometry>
            <mesh filename="meshes/wsg50/wsg50-finger-2.stl" scale="0.001 0.001 0.001"/>
        </geometry>
    </collision>
    <contact_coefficients kd="1.0" kp="1000.0" mu="0"/>
  </link>

  <joint name="wsg50_lip2_finger2_joint" type="fixed">
    <origin rpy="0 0 0" xyz="0 0 0"/>
    <parent link="wsg50_lip2_link" />
    <child link="wsg50_finger2_link" />
  </joint>

  <link name="wsg50_tip2_link">
    <inertial>
        <mass value="0.05" />
        <origin xyz="0 0 0" />
        <inertia  ixx="1.0" ixy="0.0"  ixz="0.0"  iyy="1.0"  iyz="0.0"  izz="1.0" />
    </inertial>
    <visual>
        <origin xyz="0.0 0 0" rpy="0 0 0" />
        <geometry>
            <mesh filename="meshes/wsg50/wsg50-tip-2.stl" scale="0.001 0.001 0.001"/>
        </geometry>
        <material name="blue"/>
    </visual>
    <collision>
        <origin xyz="0.0 0 0" rpy="0 0 0" />
        <geometry>
            <mesh filename="meshes/wsg50/wsg50-tip-2.stl" scale="0.001 0.001 0.001"/>
        </geometry>
    </collision>
    <contact_coefficients kd="1.0" kp="1000.0" mu="0"/>     
  </link>

  <joint name="wsg50_lip2_tip2_joint" type="fixed">
    <origin rpy="0 0 0" xyz="0 0 0"/>
    <parent link="wsg50_lip2_link" />
    <child link="wsg50_tip2_link" />
  </joint>

<!-- Realsense Camera -->

  <link name="realsense_holder_link">
    <inertial>
        <mass value="0.05" />
        <origin xyz="0 0 0" />
        <inertia  ixx="1.0" ixy="0.0"  ixz="0.0"  iyy="1.0"  iyz="0.0"  izz="1.0" />
    </inertial>
    <visual>
        <origin xyz="0.0 0 0" rpy="0 0 0" />
        <geometry>
            <mesh filename="meshes/realsense/realsense-holder.stl" scale="0.001 0.001 0.001"/>
        </geometry>
        <material name="black"/>
    </visual>
    <collision>
        <origin xyz="0.0 0 0" rpy="0 0 0" />
        <geometry>
            <mesh filename="meshes/realsense/realsense-holder.stl" scale="0.001 0.001 0.001"/>
        </geometry>
    </collision>
    <contact_coefficients kd="1.0" kp="1000.0" mu="0"/>
  </link>

  <joint name="realsense_holder_joint" type="fixed">
    <origin rpy="0 0 0" xyz="0 0 0"/>
    <parent link="wsg50_holder_link" />
    <child link="realsense_holder_link" />
  </joint>

  <link name="realsense_link">
    <inertial>
        <mass value="0.05" />
        <origin xyz="0 0 0" />
        <inertia  ixx="1.0" ixy="0.0"  ixz="0.0"  iyy="1.0"  iyz="0.0"  izz="1.0" />
    </inertial>
    <visual>
        <origin xyz="0.0 0 0" rpy="0 0 0" />
        <geometry>
            <mesh filename="meshes/realsense/realsense-D435-centered.stl" scale="0.001 0.001 0.001"/>
        </geometry>
        <material name="LightGrey"/>
    </visual>
    <collision>
        <origin xyz="0.0 0 0" rpy="0 0 0" />
        <geometry>
            <mesh filename="meshes/realsense/realsense-D435-centered.stl" scale="0.001 0.001 0.001"/>
        </geometry>
    </collision>
    <contact_coefficients kd="1.0" kp="1000.0" mu="0"/>     
  </link>

  <joint name="realsense_joint" type="fixed">
    <origin   xyz="0.11931583213806152 0.0 -0.0481053171157837 " rpy="-1.2783696937561035 0.0013367748260498004 -1.5707963705062866 "  />
    <parent link="ee_link" />
    <child link="realsense_link" />
  </joint>

</robot>

